2024-05-07 19:19:22,700 FILE: creds.py IN: create_new_token MESSAGE: Ошибка получения iam_token: HTTPConnectionPool(host='169.254.169.254', port=80): Max retries exceeded with url: /computeMetadata/v1/instance/service-accounts/default/token (Caused by NewConnectionError('<urllib3.connection.HTTPConnection object at 0x0000027AD197D1C0>: Failed to establish a new connection: [WinError 10051] Сделана попытка выполнить операцию на сокете при отключенной сети'))
